 * Serving Flask app 'quickstart' (lazy loading)
 * Environment: production
   WARNING: This is a development server. Do not use it in a production deployment.
   Use a production WSGI server instead.
 * Debug mode: on
 * Running on http://localhost:8080/ (Press CTRL+C to quit)
 * Restarting with stat
 * Debugger is active!
 * Debugger PIN: 138-813-353
127.0.0.1 - - [13/Jan/2022 16:16:11] "GET / HTTP/1.1" 200 -
127.0.0.1 - - [13/Jan/2022 16:16:13] "[32mGET /authorize HTTP/1.1[0m" 302 -
127.0.0.1 - - [13/Jan/2022 16:16:15] "[32mGET /authorize HTTP/1.1[0m" 302 -
127.0.0.1 - - [13/Jan/2022 16:16:16] "[32mGET /oauth2callback?state=X1MiT5yGV3spiL2R7RciqXcOlW9SdW&code=4%2F0AX4XfWj9L3mpyN-n9B9HdpvD1T3uz0CLEIKLdMQtfIlsDR8tGBs7x9jJvl_TloNpYi7u2A&scope=email+profile+https%3A%2F%2Fwww.googleapis.com%2Fauth%2Fuserinfo.profile+https%3A%2F%2Fmail.google.com%2F+openid+https%3A%2F%2Fwww.googleapis.com%2Fauth%2Fgmail.readonly+https%3A%2F%2Fwww.googleapis.com%2Fauth%2Fuserinfo.email&authuser=0&hd=grexit.com&prompt=none HTTP/1.1[0m" 302 -
127.0.0.1 - - [13/Jan/2022 16:16:18] "[32mGET /oauth2callback?state=LM7Cm7BXLbGaZLEx6mxUiz2SN9ciQW&code=4%2F0AX4XfWhzIRJ4WALBG4YURf261WgRnfHTslwdAkP1By58QCnE9pKcsDUmTO0LvIGoFoxO2A&scope=email+profile+https%3A%2F%2Fmail.google.com%2F+https%3A%2F%2Fwww.googleapis.com%2Fauth%2Fuserinfo.profile+https%3A%2F%2Fwww.googleapis.com%2Fauth%2Fuserinfo.email+https%3A%2F%2Fwww.googleapis.com%2Fauth%2Fgmail.readonly+openid&authuser=0&hd=grexit.com&prompt=none HTTP/1.1[0m" 302 -
127.0.0.1 - - [13/Jan/2022 16:16:25] "[32mGET /authorize HTTP/1.1[0m" 302 -
127.0.0.1 - - [13/Jan/2022 16:16:28] "[32mGET /oauth2callback?state=Xcwje2sQSiT3ULC9EAKqRj44DZfoSB&code=4%2F0AX4XfWhfiGrA5pMxf2ifK3Y94iFoMin4v6zdihwQp4k2ruXdOUfFSr3LzTbFBu0GrWmfaQ&scope=email+profile+https%3A%2F%2Fwww.googleapis.com%2Fauth%2Fuserinfo.email+https%3A%2F%2Fwww.googleapis.com%2Fauth%2Fuserinfo.profile+https%3A%2F%2Fwww.googleapis.com%2Fauth%2Fgmail.readonly+openid+https%3A%2F%2Fmail.google.com%2F&authuser=0&hd=grexit.com&prompt=none HTTP/1.1[0m" 302 -
127.0.0.1 - - [13/Jan/2022 16:16:38] "[32mGET /authorize HTTP/1.1[0m" 302 -
127.0.0.1 - - [13/Jan/2022 16:16:40] "[32mGET /oauth2callback?state=AU9VySXcm0RcPtwhsszeCyBMMNl8c2&code=4%2F0AX4XfWjF_A4QRN1hWSw_UM_ngNgNeYua2Dj26m2V0jbFGsBeEbWI8SMTZEoADf_Isbf6TQ&scope=email+profile+https%3A%2F%2Fwww.googleapis.com%2Fauth%2Fuserinfo.profile+https%3A%2F%2Fwww.googleapis.com%2Fauth%2Fuserinfo.email+https%3A%2F%2Fwww.googleapis.com%2Fauth%2Fgmail.readonly+openid+https%3A%2F%2Fmail.google.com%2F&authuser=0&hd=grexit.com&prompt=none HTTP/1.1[0m" 302 -
127.0.0.1 - - [13/Jan/2022 16:16:41] "[35m[1mGET /listen HTTP/1.1[0m" 500 -
Traceback (most recent call last):
  File "/Library/Frameworks/Python.framework/Versions/3.10/lib/python3.10/site-packages/flask/app.py", line 2091, in __call__
    return self.wsgi_app(environ, start_response)
  File "/Library/Frameworks/Python.framework/Versions/3.10/lib/python3.10/site-packages/flask/app.py", line 2076, in wsgi_app
    response = self.handle_exception(e)
  File "/Library/Frameworks/Python.framework/Versions/3.10/lib/python3.10/site-packages/flask/app.py", line 2073, in wsgi_app
    response = self.full_dispatch_request()
  File "/Library/Frameworks/Python.framework/Versions/3.10/lib/python3.10/site-packages/flask/app.py", line 1518, in full_dispatch_request
    rv = self.handle_user_exception(e)
  File "/Library/Frameworks/Python.framework/Versions/3.10/lib/python3.10/site-packages/flask/app.py", line 1516, in full_dispatch_request
    rv = self.dispatch_request()
  File "/Library/Frameworks/Python.framework/Versions/3.10/lib/python3.10/site-packages/flask/app.py", line 1502, in dispatch_request
    return self.ensure_sync(self.view_functions[rule.endpoint])(**req.view_args)
  File "/Users/sathwik/Desktop/mini-hiver/quickstart.py", line 75, in test_api_request
    emailId = gmailInstance.users().getProfile(userId="me").execute()
  File "/Library/Frameworks/Python.framework/Versions/3.10/lib/python3.10/site-packages/googleapiclient/_helpers.py", line 131, in positional_wrapper
    return wrapped(*args, **kwargs)
  File "/Library/Frameworks/Python.framework/Versions/3.10/lib/python3.10/site-packages/googleapiclient/http.py", line 922, in execute
    resp, content = _retry_request(
  File "/Library/Frameworks/Python.framework/Versions/3.10/lib/python3.10/site-packages/googleapiclient/http.py", line 221, in _retry_request
    raise exception
  File "/Library/Frameworks/Python.framework/Versions/3.10/lib/python3.10/site-packages/googleapiclient/http.py", line 190, in _retry_request
    resp, content = http.request(uri, method, *args, **kwargs)
  File "/Library/Frameworks/Python.framework/Versions/3.10/lib/python3.10/site-packages/google_auth_httplib2.py", line 218, in request
    response, content = self.http.request(
  File "/Library/Frameworks/Python.framework/Versions/3.10/lib/python3.10/site-packages/httplib2/__init__.py", line 1725, in request
    (response, content) = self._request(
  File "/Library/Frameworks/Python.framework/Versions/3.10/lib/python3.10/site-packages/httplib2/__init__.py", line 1441, in _request
    (response, content) = self._conn_request(conn, request_uri, method, body, headers)
  File "/Library/Frameworks/Python.framework/Versions/3.10/lib/python3.10/site-packages/httplib2/__init__.py", line 1393, in _conn_request
    response = conn.getresponse()
  File "/Library/Frameworks/Python.framework/Versions/3.10/lib/python3.10/http/client.py", line 1374, in getresponse
    response.begin()
  File "/Library/Frameworks/Python.framework/Versions/3.10/lib/python3.10/http/client.py", line 318, in begin
    version, status, reason = self._read_status()
  File "/Library/Frameworks/Python.framework/Versions/3.10/lib/python3.10/http/client.py", line 279, in _read_status
    line = str(self.fp.readline(_MAXLINE + 1), "iso-8859-1")
  File "/Library/Frameworks/Python.framework/Versions/3.10/lib/python3.10/socket.py", line 705, in readinto
    return self._sock.recv_into(b)
  File "/Library/Frameworks/Python.framework/Versions/3.10/lib/python3.10/ssl.py", line 1273, in recv_into
    return self.read(nbytes, buffer)
  File "/Library/Frameworks/Python.framework/Versions/3.10/lib/python3.10/ssl.py", line 1129, in read
    return self._sslobj.read(len, buffer)
ssl.SSLError: [SSL: DECRYPTION_FAILED_OR_BAD_RECORD_MAC] decryption failed or bad record mac (_ssl.c:2536)
127.0.0.1 - - [13/Jan/2022 16:16:41] "GET /listen?__debugger__=yes&cmd=resource&f=style.css HTTP/1.1" 200 -
127.0.0.1 - - [13/Jan/2022 16:16:41] "GET /listen?__debugger__=yes&cmd=resource&f=debugger.js HTTP/1.1" 200 -
127.0.0.1 - - [13/Jan/2022 16:16:41] "GET /listen?__debugger__=yes&cmd=resource&f=console.png HTTP/1.1" 200 -
127.0.0.1 - - [13/Jan/2022 16:16:41] "GET /listen?__debugger__=yes&cmd=resource&f=ubuntu.ttf HTTP/1.1" 200 -
127.0.0.1 - - [13/Jan/2022 16:16:42] "[35m[1mGET /listen HTTP/1.1[0m" 500 -
Traceback (most recent call last):
  File "/Library/Frameworks/Python.framework/Versions/3.10/lib/python3.10/site-packages/flask/app.py", line 2091, in __call__
    return self.wsgi_app(environ, start_response)
  File "/Library/Frameworks/Python.framework/Versions/3.10/lib/python3.10/site-packages/flask/app.py", line 2076, in wsgi_app
    response = self.handle_exception(e)
  File "/Library/Frameworks/Python.framework/Versions/3.10/lib/python3.10/site-packages/flask/app.py", line 2073, in wsgi_app
    response = self.full_dispatch_request()
  File "/Library/Frameworks/Python.framework/Versions/3.10/lib/python3.10/site-packages/flask/app.py", line 1518, in full_dispatch_request
    rv = self.handle_user_exception(e)
  File "/Library/Frameworks/Python.framework/Versions/3.10/lib/python3.10/site-packages/flask/app.py", line 1516, in full_dispatch_request
    rv = self.dispatch_request()
  File "/Library/Frameworks/Python.framework/Versions/3.10/lib/python3.10/site-packages/flask/app.py", line 1502, in dispatch_request
    return self.ensure_sync(self.view_functions[rule.endpoint])(**req.view_args)
  File "/Users/sathwik/Desktop/mini-hiver/quickstart.py", line 97, in test_api_request
    metadataMessage2 = gmailInstance2.users().messages().get(userId="me", id=pMessage["id"], format="metadata").execute()
  File "/Library/Frameworks/Python.framework/Versions/3.10/lib/python3.10/site-packages/googleapiclient/_helpers.py", line 131, in positional_wrapper
    return wrapped(*args, **kwargs)
  File "/Library/Frameworks/Python.framework/Versions/3.10/lib/python3.10/site-packages/googleapiclient/http.py", line 937, in execute
    raise HttpError(resp, content, uri=self.uri)
googleapiclient.errors.HttpError: <HttpError 404 when requesting https://gmail.googleapis.com/gmail/v1/users/me/messages/17e421ffbb140c8f?format=metadata&alt=json returned "Requested entity was not found.". Details: "[{'message': 'Requested entity was not found.', 'domain': 'global', 'reason': 'notFound'}]">
127.0.0.1 - - [13/Jan/2022 16:17:04] "[35m[1mGET /listen HTTP/1.1[0m" 500 -
Traceback (most recent call last):
  File "/Library/Frameworks/Python.framework/Versions/3.10/lib/python3.10/site-packages/flask/app.py", line 2091, in __call__
    return self.wsgi_app(environ, start_response)
  File "/Library/Frameworks/Python.framework/Versions/3.10/lib/python3.10/site-packages/flask/app.py", line 2076, in wsgi_app
    response = self.handle_exception(e)
  File "/Library/Frameworks/Python.framework/Versions/3.10/lib/python3.10/site-packages/flask/app.py", line 2073, in wsgi_app
    response = self.full_dispatch_request()
  File "/Library/Frameworks/Python.framework/Versions/3.10/lib/python3.10/site-packages/flask/app.py", line 1518, in full_dispatch_request
    rv = self.handle_user_exception(e)
  File "/Library/Frameworks/Python.framework/Versions/3.10/lib/python3.10/site-packages/flask/app.py", line 1516, in full_dispatch_request
    rv = self.dispatch_request()
  File "/Library/Frameworks/Python.framework/Versions/3.10/lib/python3.10/site-packages/flask/app.py", line 1502, in dispatch_request
    return self.ensure_sync(self.view_functions[rule.endpoint])(**req.view_args)
  File "/Users/sathwik/Desktop/mini-hiver/quickstart.py", line 91, in test_api_request
    for id2 in gmailIds:
RuntimeError: Set changed size during iteration
127.0.0.1 - - [13/Jan/2022 16:17:47] "GET /clear HTTP/1.1" 200 -
127.0.0.1 - - [13/Jan/2022 16:17:51] "GET /revoke HTTP/1.1" 200 -
127.0.0.1 - - [13/Jan/2022 16:17:56] "GET /clear HTTP/1.1" 200 -
127.0.0.1 - - [13/Jan/2022 16:18:00] "GET / HTTP/1.1" 200 -
127.0.0.1 - - [13/Jan/2022 16:18:02] "[32mGET /authorize HTTP/1.1[0m" 302 -
127.0.0.1 - - [13/Jan/2022 16:18:05] "[32mGET /oauth2callback?state=ZFPOXUf43IET6EwzlxAeOxXiwN2z9r&code=4%2F0AX4XfWhO4XROJ3bvzMmnk7_R_j4IZ1jm7mzMD9pTi401krfo3LpgGJRdhCn7axHifjPyhg&scope=email+profile+https%3A%2F%2Fwww.googleapis.com%2Fauth%2Fgmail.readonly+openid+https%3A%2F%2Fwww.googleapis.com%2Fauth%2Fuserinfo.email+https%3A%2F%2Fwww.googleapis.com%2Fauth%2Fuserinfo.profile+https%3A%2F%2Fmail.google.com%2F&authuser=0&hd=grexit.com&prompt=none HTTP/1.1[0m" 302 -
127.0.0.1 - - [13/Jan/2022 16:18:07] "[32mGET /authorize HTTP/1.1[0m" 302 -
127.0.0.1 - - [13/Jan/2022 16:18:10] "[32mGET /oauth2callback?state=vCbi2JuOIZwgz1f05Xde2l1WTBH4bh&code=4%2F0AX4XfWjwZvl81j-mZszFEjxIp8zQ5BiY8Dly-m5e7gDxvHOVWh71g1EWFZ075QbnbqIZmQ&scope=email+profile+https%3A%2F%2Fwww.googleapis.com%2Fauth%2Fuserinfo.profile+https%3A%2F%2Fmail.google.com%2F+https%3A%2F%2Fwww.googleapis.com%2Fauth%2Fuserinfo.email+https%3A%2F%2Fwww.googleapis.com%2Fauth%2Fgmail.readonly+openid&authuser=0&hd=grexit.com&prompt=none HTTP/1.1[0m" 302 -
127.0.0.1 - - [13/Jan/2022 16:18:12] "[35m[1mGET /listen HTTP/1.1[0m" 500 -
127.0.0.1 - - [13/Jan/2022 16:18:12] "[35m[1mGET /listen HTTP/1.1[0m" 500 -
Traceback (most recent call last):
  File "/Library/Frameworks/Python.framework/Versions/3.10/lib/python3.10/site-packages/flask/app.py", line 2091, in __call__
    return self.wsgi_app(environ, start_response)
  File "/Library/Frameworks/Python.framework/Versions/3.10/lib/python3.10/site-packages/flask/app.py", line 2076, in wsgi_app
    response = self.handle_exception(e)
  File "/Library/Frameworks/Python.framework/Versions/3.10/lib/python3.10/site-packages/flask/app.py", line 2073, in wsgi_app
    response = self.full_dispatch_request()
  File "/Library/Frameworks/Python.framework/Versions/3.10/lib/python3.10/site-packages/flask/app.py", line 1518, in full_dispatch_request
    rv = self.handle_user_exception(e)
  File "/Library/Frameworks/Python.framework/Versions/3.10/lib/python3.10/site-packages/flask/app.py", line 1516, in full_dispatch_request
    rv = self.dispatch_request()
  File "/Library/Frameworks/Python.framework/Versions/3.10/lib/python3.10/site-packages/flask/app.py", line 1502, in dispatch_request
    return self.ensure_sync(self.view_functions[rule.endpoint])(**req.view_args)
  File "/Users/sathwik/Desktop/mini-hiver/quickstart.py", line 95, in test_api_request
    pInbox = gmailInstance2.users().threads().list(userId="me").execute()
  File "/Library/Frameworks/Python.framework/Versions/3.10/lib/python3.10/site-packages/googleapiclient/_helpers.py", line 131, in positional_wrapper
    return wrapped(*args, **kwargs)
  File "/Library/Frameworks/Python.framework/Versions/3.10/lib/python3.10/site-packages/googleapiclient/http.py", line 922, in execute
    resp, content = _retry_request(
  File "/Library/Frameworks/Python.framework/Versions/3.10/lib/python3.10/site-packages/googleapiclient/http.py", line 221, in _retry_request
    raise exception
  File "/Library/Frameworks/Python.framework/Versions/3.10/lib/python3.10/site-packages/googleapiclient/http.py", line 190, in _retry_request
    resp, content = http.request(uri, method, *args, **kwargs)
  File "/Library/Frameworks/Python.framework/Versions/3.10/lib/python3.10/site-packages/google_auth_httplib2.py", line 218, in request
    response, content = self.http.request(
  File "/Library/Frameworks/Python.framework/Versions/3.10/lib/python3.10/site-packages/httplib2/__init__.py", line 1725, in request
    (response, content) = self._request(
  File "/Library/Frameworks/Python.framework/Versions/3.10/lib/python3.10/site-packages/httplib2/__init__.py", line 1441, in _request
    (response, content) = self._conn_request(conn, request_uri, method, body, headers)
  File "/Library/Frameworks/Python.framework/Versions/3.10/lib/python3.10/site-packages/httplib2/__init__.py", line 1393, in _conn_request
    response = conn.getresponse()
  File "/Library/Frameworks/Python.framework/Versions/3.10/lib/python3.10/http/client.py", line 1374, in getresponse
    response.begin()
  File "/Library/Frameworks/Python.framework/Versions/3.10/lib/python3.10/http/client.py", line 318, in begin
    version, status, reason = self._read_status()
  File "/Library/Frameworks/Python.framework/Versions/3.10/lib/python3.10/http/client.py", line 279, in _read_status
    line = str(self.fp.readline(_MAXLINE + 1), "iso-8859-1")
  File "/Library/Frameworks/Python.framework/Versions/3.10/lib/python3.10/socket.py", line 705, in readinto
    return self._sock.recv_into(b)
  File "/Library/Frameworks/Python.framework/Versions/3.10/lib/python3.10/ssl.py", line 1273, in recv_into
    return self.read(nbytes, buffer)
  File "/Library/Frameworks/Python.framework/Versions/3.10/lib/python3.10/ssl.py", line 1129, in read
    return self._sslobj.read(len, buffer)
ssl.SSLError: [SSL: WRONG_VERSION_NUMBER] wrong version number (_ssl.c:2536)
127.0.0.1 - - [13/Jan/2022 16:18:12] "GET /listen?__debugger__=yes&cmd=resource&f=style.css HTTP/1.1" 200 -
127.0.0.1 - - [13/Jan/2022 16:18:12] "GET /listen?__debugger__=yes&cmd=resource&f=debugger.js HTTP/1.1" 200 -
127.0.0.1 - - [13/Jan/2022 16:18:12] "GET /listen?__debugger__=yes&cmd=resource&f=console.png HTTP/1.1" 200 -
127.0.0.1 - - [13/Jan/2022 16:18:12] "GET /listen?__debugger__=yes&cmd=resource&f=ubuntu.ttf HTTP/1.1" 200 -
